Workbook
Name Slicer_Representative: #N/A

Sheet Sheet3
A1: Data returned for Call Count, Mar, R04 (First 1000 rows).
A3: calls[Call number] | B3: calls[Customer ID] | C3: calls[Duration] | D3: calls[Representative] | E3: calls[Date of Call] | F3: calls[Purchase Amount] | G3: calls[Satisfaction Rating] | H3: calls[FY] | I3: calls[Day of week] | J3: calls[Duration Bucket] | K3: calls[Rating rounded] | L3: calls[Date of Call (Month)] | M3: calls[Date of Call (Month Index)]
A4: Call_7417 | B4: C0011 | C4: 90 | D4: R04 | E4: 44986 | F4: 170 | G4: 3.7 | H4: 2023 | I4: Wednesday | J4: 1 to 2 hours | K4: 4 | L4: Mar | M4: 3
A5: Call_7421 | B5: C0002 | C5: 137 | D5: R04 | E5: 44986 | F5: 114 | G5: 3.2 | H5: 2023 | I5: Wednesday | J5: More than 2 hours | K5: 3 | L5: Mar | M5: 3
A6: Call_7422 | B6: C0002 | C6: 43 | D6: R04 | E6: 44986 | F6: 99 | G6: 4.7 | H6: 2023 | I6: Wednesday | J6: 30 to 60 mins | K6: 5 | L6: Mar | M6: 3
A7: Call_7423 | B7: C0010 | C7: 114 | D7: R04 | E7: 44987 | F7: 23 | G7: 4.8 | H7: 2023 | I7: Thursday | J7: 1 to 2 hours | K7: 5 | L7: Mar | M7: 3
A8: Call_7441 | B8: C0005 | C8: 75 | D8: R04 | E8: 44989 | F8: 40 | G8: 3.4 | H8: 2023 | I8: Saturday | J8: 1 to 2 hours | K8: 3 | L8: Mar | M8: 3
A9: Call_7450 | B9: C0012 | C9: 73 | D9: R04 | E9: 44991 | F9: 215 | G9: 3.6 | H9: 2023 | I9: Monday | J9: 1 to 2 hours | K9: 4 | L9: Mar | M9: 3
A10: Call_7451 | B10: C0009 | C10: 62 | D10: R04 | E10: 44991 | F10: 32 | G10: 0.7 | H10: 2023 | I10: Monday | J10: 1 to 2 hours | K10: 1 | L10: Mar | M10: 3
A11: Call_7457 | B11: C0013 | C11: 41 | D11: R04 | E11: 44992 | F11: 68 | G11: 4 | H11: 2023 | I11: Tuesday | J11: 30 to 60 mins | K11: 4 | L11: Mar | M11: 3
A12: Call_7464 | B12: C0007 | C12: 85 | D12: R04 | E12: 44995 | F12: 46 | G12: 4.9 | H12: 2023 | I12: Friday | J12: 1 to 2 hours | K12: 5 | L12: Mar | M12: 3
A13: Call_7466 | B13: C0007 | C13: 63 | D13: R04 | E13: 44995 | F13: 48 | G13: 5 | H13: 2023 | I13: Friday | J13: 1 to 2 hours | K13: 5 | L13: Mar | M13: 3
A14: Call_7468 | B14: C0007 | C14: 71 | D14: R04 | E14: 44995 | F14: 105 | G14: 4 | H14: 2023 | I14: Friday | J14: 1 to 2 hours | K14: 4 | L14: Mar | M14: 3
A15: Call_7469 | B15: C0004 | C15: 100 | D15: R04 | E15: 44996 | F15: 44 | G15: 3.6 | H15: 2023 | I15: Saturday | J15: 1 to 2 hours | K15: 4 | L15: Mar | M15: 3
... A33: Call_7565 | B33: C0005 | C33: 56 | D33: R04 | E33: 45014 | F33: 88 | G33: 4.1 | H33: 2023 | I33: Wednesday | J33: 30 to 60 mins | K33: 4 | L33: Mar | M33: 3

Sheet Pivots
A3: Call Count | B3: Total Amount | C3: Total Duration | D3: Avg Rating | E3: 5* calls
A4: 1000 | B4: 96623 | C4: 89850 | D4: 3.8854 | E4: 307
A9: Call Count | B9: Total Amount | C9: Total Duration | D9: Avg Rating | E9: 5* calls
A10: 200 | B10: 20104 | C10: 18209 | D10: 3.8825 | E10: 51
A24: Row Labels | B24: Call Count | C24: Call Count2 | G24: Row Labels | H24: Call Count
A25: Jan | B25: 21 | C25: 21 | G25: Sunday | H25: 27
A26: Feb | B26: 18 | C26: 18 | G26: Monday | H26: 22
A27: Mar | B27: 31 | C27: 31 | G27: Tuesday | H27: 27
A28: Apr | B28: 20 | C28: 20 | G28: Wednesday | H28: 27
A29: May | B29: 8 | C29: 8 | G29: Thursday | H29: 27
A30: Jun | B30: 12 | C30: 12 | G30: Friday | H30: 32
A31: Jul | B31: 12 | C31: 12 | G31: Saturday | H31: 38
A32: Aug | B32: 7 | C32: 7 | G32: Grand Total | H32: 200
A33: Sep | B33: 20 | C33: 20
A34: Oct | B34: 24 | C34: 24
A35: Nov | B35: 12 | C35: 12
A36: Dec | B36: 15 | C36: 15
A37: Grand Total | B37: 200 | C37: 200
F52: For Graph | I52: Selected Rep | J52: =F67 -> R05
F53: Rep | G53: Calls | H53: Amount | I53: Sel.Calls | J53: Sel. Amount
A54: Row Labels | B54: Call Count | C54: Total Amount | F54: {=A55:C59} -> R01 | G54: 189 | H54: 18415 | I54: =IF(F54=$J$52,G54,NA()) -> #N/A | J54: =IF(F54=$J$52,H54,NA()) -> #N/A
A55: R01 | B55: 189 | C55: 18415 | F55: R02 | G55: 218 | H55: 20581 | I55: =IF(F55=$J$52,G55,NA()) -> #N/A | J55: =IF(F55=$J$52,H55,NA()) -> #N/A
A56: R02 | B56: 218 | C56: 20581 | F56: R03 | G56: 207 | H56: 20872 | I56: =IF(F56=$J$52,G56,NA()) -> #N/A | J56: =IF(F56=$J$52,H56,NA()) -> #N/A
A57: R03 | B57: 207 | C57: 20872 | F57: R04 | G57: 186 | H57: 16651 | I57: =IF(F57=$J$52,G57,NA()) -> #N/A | J57: =IF(F57=$J$52,H57,NA()) -> #N/A
A58: R04 | B58: 186 | C58: 16651 | F58: R05 | G58: 200 | H58: 20104 | I58: =IF(F58=$J$52,G58,NA()) -> 200 | J58: =IF(F58=$J$52,H58,NA()) -> 20104
A59: R05 | B59: 200 | C59: 20104
A60: Grand Total | B60: 1000 | C60: 96623
I64: Rep Summary
I65: % of calls | J65: =A10/A4 -> 0.2
F66: Row Labels | I66: Calls | J66: =_xlfn.XLOOKUP(F67,F54:F58,G54:G58) -> 200
F67: R05 | I67: Amount | J67: =_xlfn.XLOOKUP(F67,F54:F58,H54:H58) -> 20104
I69: Call Rank | J69: =_xlfn.RANK.AVG(J66,G54:G58) -> 3
I70: Amount Rank | J70: =_xlfn.RANK.AVG(J67,H54:H58) -> 3
I72: Labels:
J73: ="% of calls: " & TEXT(J65,"0%") -> % of calls: 20%
J74: ="Call Rank: "&J69 -> Call Rank: 3
A75: Call Count | B75: Column Labels | J75: ="Amount Rank: " & J70 -> Amount Rank: 3
A76: Row Labels | B76: Female | C76: Male | D76: Grand Total
A77: Cincinnati | B77: 144 | C77: 132 | D77: 276
A78: Cleveland | B78: 326 | C78: 63 | D78: 389 | I78: Image: | J78: =_xlfn.XLOOKUP(F67,Assets!$E$14:$E$18,Assets!$F$14:$F$18) -> 0
...

Sheet Data
B1: Call Centre Data
B3: Call number | C3: Customer ID | D3: Duration | E3: Representative | F3: Date of Call | G3: Purchase Amount | H3: Satisfaction Rating | I3: FY | J3: Day of week | K3: Duration Bucket | L3: Rating rounded | Q3: Customer ID | R3: Gedner | S3: Age | T3: City
B4: Call_7271 | C4: C0003 | D4: 116 | E4: R05 | F4: 44927 | G4: 128 | H4: 4.9 | I4: =IF(MONTH(calls[[#This Row],[Date of Call]])<=6, YEAR(calls[[#This Row],[Date of Call]]), YEAR(calls[[#This Row],[Date of Call]])+1) -> 2023 | J4: =TEXT(calls[[#This Row],[Date of Call]],"DDDD") -> Sunday | K4: {=_xlfn.IFS(calls[[#This Row],[Duration]]<=10,"Under 10 mins", calls[[#This Row],[Duration]]<=30, "10 to 30 mins", calls[[#This Row],[Duration]]<=60, "30 to 60 mins", calls[[#This Row],[Duration]]<=120, "1 to 2 hours", TRUE, "More than 2 hours")} -> 1 to 2 hours | L4: =ROUND(calls[[#This Row],[Satisfaction Rating]],0) -> 5 | Q4: C0001 | R4: Male | S4: 41 | T4: Columbus
B5: Call_7272 | C5: C0004 | D5: 119 | E5: R05 | F5: 44927 | G5: 135 | H5: 2.9 | I5: =IF(MONTH(calls[[#This Row],[Date of Call]])<=6, YEAR(calls[[#This Row],[Date of Call]]), YEAR(calls[[#This Row],[Date of Call]])+1) -> 2023 | J5: =TEXT(calls[[#This Row],[Date of Call]],"DDDD") -> Sunday | K5: {=_xlfn.IFS(calls[[#This Row],[Duration]]<=10,"Under 10 mins", calls[[#This Row],[Duration]]<=30, "10 to 30 mins", calls[[#This Row],[Duration]]<=60, "30 to 60 mins", calls[[#This Row],[Duration]]<=120, "1 to 2 hours", TRUE, "More than 2 hours")} -> 1 to 2 hours | L5: =ROUND(calls[[#This Row],[Satisfaction Rating]],0) -> 3 | Q5: C0002 | R5: Male | S5: 31 | T5: Cleveland
B6: Call_7273 | C6: C0005 | D6: 68 | E6: R02 | F6: 44927 | G6: 66 | H6: 4.7 | I6: =IF(MONTH(calls[[#This Row],[Date of Call]])<=6, YEAR(calls[[#This Row],[Date of Call]]), YEAR(calls[[#This Row],[Date of Call]])+1) -> 2023 | J6: =TEXT(calls[[#This Row],[Date of Call]],"DDDD") -> Sunday | K6: {=_xlfn.IFS(calls[[#This Row],[Duration]]<=10,"Under 10 mins", calls[[#This Row],[Duration]]<=30, "10 to 30 mins", calls[[#This Row],[Duration]]<=60, "30 to 60 mins", calls[[#This Row],[Duration]]<=120, "1 to 2 hours", TRUE, "More than 2 hours")} -> 1 to 2 hours | L6: =ROUND(calls[[#This Row],[Satisfaction Rating]],0) -> 5 | Q6: C0003 | R6: Male | S6: 26 | T6: Cincinnati
B7: Call_7274 | C7: C0014 | D7: 119 | E7: R02 | F7: 44927 | G7: 22 | H7: 2.9 | I7: =IF(MONTH(calls[[#This Row],[Date of Call]])<=6, YEAR(calls[[#This Row],[Date of Call]]), YEAR(calls[[#This Row],[Date of Call]])+1) -> 2023 | J7: =TEXT(calls[[#This Row],[Date of Call]],"DDDD") -> Sunday | K7: {=_xlfn.IFS(calls[[#This Row],[Duration]]<=10,"Under 10 mins", calls[[#This Row],[Duration]]<=30, "10 to 30 mins", calls[[#This Row],[Duration]]<=60, "30 to 60 mins", calls[[#This Row],[Duration]]<=120, "1 to 2 hours", TRUE, "More than 2 hours")} -> 1 to 2 hours | L7: =ROUND(calls[[#This Row],[Satisfaction Rating]],0) -> 3 | Q7: C0004 | R7: Male | S7: 36 | T7: Cincinnati
B8: Call_7275 | C8: C0011 | D8: 128 | E8: R01 | F8: 44928 | G8: 31 | H8: 2.8 | I8: =IF(MONTH(calls[[#This Row],[Date of Call]])<=6, YEAR(calls[[#This Row],[Date of Call]]), YEAR(calls[[#This Row],[Date of Call]])+1) -> 2023 | J8: =TEXT(calls[[#This Row],[Date of Call]],"DDDD") -> Monday | K8: {=_xlfn.IFS(calls[[#This Row],[Duration]]<=10,"Under 10 mins", calls[[#This Row],[Duration]]<=30, "10 to 30 mins", calls[[#This Row],[Duration]]<=60, "30 to 60 mins", calls[[#This Row],[Duration]]<=120, "1 to 2 hours", TRUE, "More than 2 hours")} -> More than 2 hours | L8: =ROUND(calls[[#This Row],[Satisfaction Rating]],0) -> 3 | Q8: C0005 | R8: Male | S8: 37 | T8: Columbus
B9: Call_7276 | C9: C0011 | D9: 49 | E9: R02 | F9: 44929 | G9: 135 | H9: 4.8 | I9: =IF(MONTH(calls[[#This Row],[Date of Call]])<=6, YEAR(calls[[#This Row],[Date of Call]]), YEAR(calls[[#This Row],[Date of Call]])+1) -> 2023 | J9: =TEXT(calls[[#This Row],[Date of Call]],"DDDD") -> Tuesday | K9: {=_xlfn.IFS(calls[[#This Row],[Duration]]<=10,"Under 10 mins", calls[[#This Row],[Duration]]<=30, "10 to 30 mins", calls[[#This Row],[Duration]]<=60, "30 to 60 mins", calls[[#This Row],[Duration]]<=120, "1 to 2 hours", TRUE, "More than 2 hours")} -> 30 to 60 mins | L9: =ROUND(calls[[#This Row],[Satisfaction Rating]],0) -> 5 | Q9: C0006 | R9: Male | S9: 23 | T9: Columbus
B10: Call_7277 | C10: C0007 | D10: 84 | E10: R05 | F10: 44929 | G10: 60 | H10: 4.7 | I10: =IF(MONTH(calls[[#This Row],[Date of Call]])<=6, YEAR(calls[[#This Row],[Date of Call]]), YEAR(calls[[#This Row],[Date of Call]])+1) -> 2023 | J10: =TEXT(calls[[#This Row],[Date of Call]],"DDDD") -> Tuesday | K10: {=_xlfn.IFS(calls[[#This Row],[Duration]]<=10,"Under 10 mins", calls[[#This Row],[Duration]]<=30, "10 to 30 mins", calls[[#This Row],[Duration]]<=60, "30 to 60 mins", calls[[#This Row],[Duration]]<=120, "1 to 2 hours", TRUE, "More than 2 hours")} -> 1 to 2 hours | L10: =ROUND(calls[[#This Row],[Satisfaction Rating]],0) -> 5 | Q10: C0007 | R10: Female | S10: 22 | T10: Cleveland
B11: Call_7278 | C11: C0003 | D11: 103 | E11: R04 | F11: 44929 | G11: 148 | H11: 4.4 | I11: =IF(MONTH(calls[[#This Row],[Date of Call]])<=6, YEAR(calls[[#This Row],[Date of Call]]), YEAR(calls[[#This Row],[Date of Call]])+1) -> 2023 | J11: =TEXT(calls[[#This Row],[Date of Call]],"DDDD") -> Tuesday | K11: {=_xlfn.IFS(calls[[#This Row],[Duration]]<=10,"Under 10 mins", calls[[#This Row],[Duration]]<=30, "10 to 30 mins", calls[[#This Row],[Duration]]<=60, "30 to 60 mins", calls[[#This Row],[Duration]]<=120, "1 to 2 hours", TRUE, "More than 2 hours")} -> 1 to 2 hours | L11: =ROUND(calls[[#This Row],[Satisfaction Rating]],0) -> 4 | Q11: C0008 | R11: Female | S11: 42 | T11: Cleveland
B12: Call_7279 | C12: C0005 | D12: 31 | E12: R02 | F12: 44929 | G12: 135 | H12: 3.6 | I12: =IF(MONTH(calls[[#This Row],[Date of Call]])<=6, YEAR(calls[[#This Row],[Date of Call]]), YEAR(calls[[#This Row],[Date of Call]])+1) -> 2023 | J12: =TEXT(calls[[#This Row],[Date of Call]],"DDDD") -> Tuesday | K12: {=_xlfn.IFS(calls[[#This Row],[Duration]]<=10,"Under 10 mins", calls[[#This Row],[Duration]]<=30, "10 to 30 mins", calls[[#This Row],[Duration]]<=60, "30 to 60 mins", calls[[#This Row],[Duration]]<=120, "1 to 2 hours", TRUE, "More than 2 hours")} -> 30 to 60 mins | L12: =ROUND(calls[[#This Row],[Satisfaction Rating]],0) -> 4 | Q12: C0009 | R12: Female | S12: 25 | T12: Columbus
B13: Call_7280 | C13: C0010 | D13: 44 | E13: R03 | F13: 44929 | G13: 105 | H13: 2.9 | I13: =IF(MONTH(calls[[#This Row],[Date of Call]])<=6, YEAR(calls[[#This Row],[Date of Call]]), YEAR(calls[[#This Row],[Date of Call]])+1) -> 2023 | J13: =TEXT(calls[[#This Row],[Date of Call]],"DDDD") -> Tuesday | K13: {=_xlfn.IFS(calls[[#This Row],[Duration]]<=10,"Under 10 mins", calls[[#This Row],[Duration]]<=30, "10 to 30 mins", calls[[#This Row],[Duration]]<=60, "30 to 60 mins", calls[[#This Row],[Duration]]<=120, "1 to 2 hours", TRUE, "More than 2 hours")} -> 30 to 60 mins | L13: =ROUND(calls[[#This Row],[Satisfaction Rating]],0) -> 3 | Q13: C0010 | R13: Female | S13: 30 | T13: Cleveland
B14: Call_7281 | C14: C0011 | D14: 102 | E14: R02 | F14: 44929 | G14: 69 | H14: 4.9 | I14: =IF(MONTH(calls[[#This Row],[Date of Call]])<=6, YEAR(calls[[#This Row],[Date of Call]]), YEAR(calls[[#This Row],[Date of Call]])+1) -> 2023 | J14: =TEXT(calls[[#This Row],[Date of Call]],"DDDD") -> Tuesday | K14: {=_xlfn.IFS(calls[[#This Row],[Duration]]<=10,"Under 10 mins", calls[[#This Row],[Duration]]<=30, "10 to 30 mins", calls[[#This Row],[Duration]]<=60, "30 to 60 mins", calls[[#This Row],[Duration]]<=120, "1 to 2 hours", TRUE, "More than 2 hours")} -> 1 to 2 hours | L14: =ROUND(calls[[#This Row],[Satisfaction Rating]],0) -> 5 | Q14: C0011 | R14: Female | S14: 30 | T14: Cincinnati
B15: Call_7282 | C15: C0013 | D15: 135 | E15: R05 | F15: 44929 | G15: 46 | H15: 3.4 | I15: =IF(MONTH(calls[[#This Row],[Date of Call]])<=6, YEAR(calls[[#This Row],[Date of Call]]), YEAR(calls[[#This Row],[Date of Call]])+1) -> 2023 | J15: =TEXT(calls[[#This Row],[Date of Call]],"DDDD") -> Tuesday | K15: {=_xlfn.IFS(calls[[#This Row],[Duration]]<=10,"Under 10 mins", calls[[#This Row],[Duration]]<=30, "10 to 30 mins", calls[[#This Row],[Duration]]<=60, "30 to 60 mins", calls[[#This Row],[Duration]]<=120, "1 to 2 hours", TRUE, "More than 2 hours")} -> More than 2 hours | L15: =ROUND(calls[[#This Row],[Satisfaction Rating]],0) -> 3 | Q15: C0012 | R15: Female | S15: 28 | T15: Cincinnati
... B18: Call_7285 | C18: C0013 | D18: 48 | E18: R01 | F18: 44930 | G18: 68 | H18: 4.9 | I18: =IF(MONTH(calls[[#This Row],[Date of Call]])<=6, YEAR(calls[[#This Row],[Date of Call]]), YEAR(calls[[#This Row],[Date of Call]])+1) -> 2023 | J18: =TEXT(calls[[#This Row],[Date of Call]],"DDDD") -> Wednesday | K18: {=_xlfn.IFS(calls[[#This Row],[Duration]]<=10,"Under 10 mins", calls[[#This Row],[Duration]]<=30, "10 to 30 mins", calls[[#This Row],[Duration]]<=60, "30 to 60 mins", calls[[#This Row],[Duration]]<=120, "1 to 2 hours", TRUE, "More than 2 hours")} -> 30 to 60 mins | L18: =ROUND(calls[[#This Row],[Satisfaction Rating]],0) -> 5 | Q18: C0015 | R18: Female | S18: 43 | T18: Cleveland
B19: Call_7286 | C19: C0010 | D19: 176 | E19: R05 | F19: 44931 | G19: 24 | H19: 4.8 | I19: =IF(MONTH(calls[[#This Row],[Date of Call]])<=6, YEAR(calls[[#This Row],[Date of Call]]), YEAR(calls[[#This Row],[Date of Call]])+1) -> 2023 | J19: =TEXT(calls[[#This Row],[Date of Call]],"DDDD") -> Thursday | K19: {=_xlfn.IFS(calls[[#This Row],[Duration]]<=10,"Under 10 mins", calls[[#This Row],[Duration]]<=30, "10 to 30 mins", calls[[#This Row],[Duration]]<=60, "30 to 60 mins", calls[[#This Row],[Duration]]<=120, "1 to 2 hours", TRUE, "More than 2 hours")} -> More than 2 hours | L19: =ROUND(calls[[#This Row],[Satisfaction Rating]],0) -> 5
B20: Call_7287 | C20: C0010 | D20: 99 | E20: R01 | F20: 44931 | G20: 195 | H20: 3.9 | I20: =IF(MONTH(calls[[#This Row],[Date of Call]])<=6, YEAR(calls[[#This Row],[Date of Call]]), YEAR(calls[[#This Row],[Date of Call]])+1) -> 2023 | J20: =TEXT(calls[[#This Row],[Date of Call]],"DDDD") -> Thursday | K20: {=_xlfn.IFS(calls[[#This Row],[Duration]]<=10,"Under 10 mins", calls[[#This Row],[Duration]]<=30, "10 to 30 mins", calls[[#This Row],[Duration]]<=60, "30 to 60 mins", calls[[#This Row],[Duration]]<=120, "1 to 2 hours", TRUE, "More than 2 hours")} -> 1 to 2 hours | L20: =ROUND(calls[[#This Row],[Satisfaction Rating]],0) -> 4
B21: Call_7288 | C21: C0009 | D21: 28 | E21: R03 | F21: 44931 | G21: 28 | H21: 3.8 | I21: =IF(MONTH(calls[[#This Row],[Date of Call]])<=6, YEAR(calls[[#This Row],[Date of Call]]), YEAR(calls[[#This Row],[Date of Call]])+1) -> 2023 | J21: =TEXT(calls[[#This Row],[Date of Call]],"DDDD") -> Thursday | K21: {=_xlfn.IFS(calls[[#This Row],[Duration]]<=10,"Under 10 mins", calls[[#This Row],[Duration]]<=30, "10 to 30 mins", calls[[#This Row],[Duration]]<=60, "30 to 60 mins", calls[[#This Row],[Duration]]<=120, "1 to 2 hours", TRUE, "More than 2 hours")} -> 10 to 30 mins | L21: =ROUND(calls[[#This Row],[Satisfaction Rating]],0) -> 4
B22: Call_7289 | C22: C0007 | D22: 54 | E22: R02 | F22: 44931 | G22: 170 | H22: 4.3 | I22: =IF(MONTH(calls[[#This Row],[Date of Call]])<=6, YEAR(calls[[#This Row],[Date of Call]]), YEAR(calls[[#This Row],[Date of Call]])+1) -> 2023 | J22: =TEXT(calls[[#This Row],[Date of Call]],"DDDD") -> Thursday | K22: {=_xlfn.IFS(calls[[#This Row],[Duration]]<=10,"Under 10 mins", calls[[#This Row],[Duration]]<=30, "10 to 30 mins", calls[[#This Row],[Duration]]<=60, "30 to 60 mins", calls[[#This Row],[Duration]]<=120, "1 to 2 hours", TRUE, "More than 2 hours")} -> 30 to 60 mins | L22: =ROUND(calls[[#This Row],[Satisfaction Rating]],0) -> 4
B23: Call_7290 | C23: C0006 | D23: 48 | E23: R05 | F23: 44932 | G23: 30 | H23: 4.4 | I23: =IF(MONTH(calls[[#This Row],[Date of Call]])<=6, YEAR(calls[[#This Row],[Date of Call]]), YEAR(calls[[#This Row],[Date of Call]])+1) -> 2023 | J23: =TEXT(calls[[#This Row],[Date of Call]],"DDDD") -> Friday | K23: {=_xlfn.IFS(calls[[#This Row],[Duration]]<=10,"Under 10 mins", calls[[#This Row],[Duration]]<=30, "10 to 30 mins", calls[[#This Row],[Duration]]<=60, "30 to 60 mins", calls[[#This Row],[Duration]]<=120, "1 to 2 hours", TRUE, "More than 2 hours")} -> 30 to 60 mins | L23: =ROUND(calls[[#This Row],[Satisfaction Rating]],0) -> 4
B24: Call_7291 | C24: C0004 | D24: 128 | E24: R05 | F24: 44932 | G24: 72 | H24: 5 | I24: =IF(MONTH(calls[[#This Row],[Date of Call]])<=6, YEAR(calls[[#This Row],[Date of Call]]), YEAR(calls[[#This Row],[Date of Call]])+1) -> 2023 | J24: =TEXT(calls[[#This Row],[Date of Call]],"DDDD") -> Friday | K24: {=_xlfn.IFS(calls[[#This Row],[Duration]]<=10,"Under 10 mins", calls[[#This Row],[Duration]]<=30, "10 to 30 mins", calls[[#This Row],[Duration]]<=60, "30 to 60 mins", calls[[#This Row],[Duration]]<=120, "1 to 2 hours", TRUE, "More than 2 hours")} -> More than 2 hours | L24: =ROUND(calls[[#This Row],[Satisfaction Rating]],0) -> 5
B25: Call_7292 | C25: C0004 | D25: 38 | E25: R04 | F25: 44933 | G25: 92 | H25: 4.9 | I25: =IF(MONTH(calls[[#This Row],[Date of Call]])<=6, YEAR(calls[[#This Row],[Date of Call]]), YEAR(calls[[#This Row],[Date of Call]])+1) -> 2023 | J25: =TEXT(calls[[#This Row],[Date of Call]],"DDDD") -> Saturday | K25: {=_xlfn.IFS(calls[[#This Row],[Duration]]<=10,"Under 10 mins", calls[[#This Row],[Duration]]<=30, "10 to 30 mins", calls[[#This Row],[Duration]]<=60, "30 to 60 mins", calls[[#This Row],[Duration]]<=120, "1 to 2 hours", TRUE, "More than 2 hours")} -> 30 to 60 mins | L25: =ROUND(calls[[#This Row],[Satisfaction Rating]],0) -> 5
B26: Call_7293 | C26: C0003 | D26: 67 | E26: R04 | F26: 44934 | G26: 165 | H26: 4.5 | I26: =IF(MONTH(calls[[#This Row],[Date of Call]])<=6, YEAR(calls[[#This Row],[Date of Call]]), YEAR(calls[[#This Row],[Date of Call]])+1) -> 2023 | J26: =TEXT(calls[[#This Row],[Date of Call]],"DDDD") -> Sunday | K26: {=_xlfn.IFS(calls[[#This Row],[Duration]]<=10,"Under 10 mins", calls[[#This Row],[Duration]]<=30, "10 to 30 mins", calls[[#This Row],[Duration]]<=60, "30 to 60 mins", calls[[#This Row],[Duration]]<=120, "1 to 2 hours", TRUE, "More than 2 hours")} -> 1 to 2 hours | L26: =ROUND(calls[[#This Row],[Satisfaction Rating]],0) -> 5
B27: Call_7294 | C27: C0015 | D27: 58 | E27: R02 | F27: 44934 | G27: 140 | H27: 2.1 | I27: =IF(MONTH(calls[[#This Row],[Date of Call]])<=6, YEAR(calls[[#This Row],[Date of Call]]), YEAR(calls[[#This Row],[Date of Call]])+1) -> 2023 | J27: =TEXT(calls[[#This Row],[Date of Call]],"DDDD") -> Sunday | K27: {=_xlfn.IFS(calls[[#This Row],[Duration]]<=10,"Under 10 mins", calls[[#This Row],[Duration]]<=30, "10 to 30 mins", calls[[#This Row],[Duration]]<=60, "30 to 60 mins", calls[[#This Row],[Duration]]<=120, "1 to 2 hours", TRUE, "More than 2 hours")} -> 30 to 60 mins | L27: =ROUND(calls[[#This Row],[Satisfaction Rating]],0) -> 2
B28: Call_7295 | C28: C0010 | D28: 54 | E28: R01 | F28: 44934 | G28: 111 | H28: 3.3 | I28: =IF(MONTH(calls[[#This Row],[Date of Call]])<=6, YEAR(calls[[#This Row],[Date of Call]]), YEAR(calls[[#This Row],[Date of Call]])+1) -> 2023 | J28: =TEXT(calls[[#This Row],[Date of Call]],"DDDD") -> Sunday | K28: {=_xlfn.IFS(calls[[#This Row],[Duration]]<=10,"Under 10 mins", calls[[#This Row],[Duration]]<=30, "10 to 30 mins", calls[[#This Row],[Duration]]<=60, "30 to 60 mins", calls[[#This Row],[Duration]]<=120, "1 to 2 hours", TRUE, "More than 2 hours")} -> 30 to 60 mins | L28: =ROUND(calls[[#This Row],[Satisfaction Rating]],0) -> 3
B29: Call_7296 | C29: C0012 | D29: 28 | E29: R05 | F29: 44935 | G29: 63 | H29: 4.1 | I29: =IF(MONTH(calls[[#This Row],[Date of Call]])<=6, YEAR(calls[[#This Row],[Date of Call]]), YEAR(calls[[#This Row],[Date of Call]])+1) -> 2023 | J29: =TEXT(calls[[#This Row],[Date of Call]],"DDDD") -> Monday | K29: {=_xlfn.IFS(calls[[#This Row],[Duration]]<=10,"Under 10 mins", calls[[#This Row],[Duration]]<=30, "10 to 30 mins", calls[[#This Row],[Duration]]<=60, "30 to 60 mins", calls[[#This Row],[Duration]]<=120, "1 to 2 hours", TRUE, "More than 2 hours")} -> 10 to 30 mins | L29: =ROUND(calls[[#This Row],[Satisfaction Rating]],0) -> 4
B30: Call_7297 | C30: C0002 | D30: 73 | E30: R05 | F30: 44935 | G30: 80 | H30: 4.2 | I30: =IF(MONTH(calls[[#This Row],[Date of Call]])<=6, YEAR(calls[[#This Row],[Date of Call]]), YEAR(calls[[#This Row],[Date of Call]])+1) -> 2023 | J30: =TEXT(calls[[#This Row],[Date of Call]],"DDDD") -> Monday | K30: {=_xlfn.IFS(calls[[#This Row],[Duration]]<=10,"Under 10 mins", calls[[#This Row],[Duration]]<=30, "10 to 30 mins", calls[[#This Row],[Duration]]<=60, "30 to 60 mins", calls[[#This Row],[Duration]]<=120, "1 to 2 hours", TRUE, "More than 2 hours")} -> 1 to 2 hours | L30: =ROUND(calls[[#This Row],[Satisfaction Rating]],0) -> 4
... B1003: Call_8270 | C1003: C0009 | D1003: 114 | E1003: R01 | F1003: 45291 | G1003: 40 | H1003: 3.9 | I1003: =IF(MONTH(calls[[#This Row],[Date of Call]])<=6, YEAR(calls[[#This Row],[Date of Call]]), YEAR(calls[[#This Row],[Date of Call]])+1) -> 2024 | J1003: =TEXT(calls[[#This Row],[Date of Call]],"DDDD") -> Sunday | K1003: {=_xlfn.IFS(calls[[#This Row],[Duration]]<=10,"Under 10 mins", calls[[#This Row],[Duration]]<=30, "10 to 30 mins", calls[[#This Row],[Duration]]<=60, "30 to 60 mins", calls[[#This Row],[Duration]]<=120, "1 to 2 hours", TRUE, "More than 2 hours")} -> 1 to 2 hours | L1003: =ROUND(calls[[#This Row],[Satisfaction Rating]],0) -> 4

Sheet Customer Center Report
Q20: =Pivots!B100 -> R01 | R20: =Pivots!C100 -> R02 | S20: =Pivots!D100 -> R03 | T20: =Pivots!E100 -> R04 | U20: =Pivots!F100 -> R05 | V20: Total
P21: =IF(Pivots!A101="","",Pivots!A101) -> Cincinnati | Q21: =IF(Pivots!B101="","",Pivots!B101) | R21: =IF(Pivots!C101="","",Pivots!C101) | S21: =IF(Pivots!D101="","",Pivots!D101) | T21: =IF(Pivots!E101="","",Pivots!E101) | U21: =IF(Pivots!F101="","",Pivots!F101) | V21: =IF(Pivots!G101="","",Pivots!G101)
P22: =IF(Pivots!A102="","",Pivots!A102) -> C0003 | Q22: =IF(Pivots!B102="","",Pivots!B102) -> 891 | R22: =IF(Pivots!C102="","",Pivots!C102) -> 1332 | S22: =IF(Pivots!D102="","",Pivots!D102) -> 1282 | T22: =IF(Pivots!E102="","",Pivots!E102) -> 739 | U22: =IF(Pivots!F102="","",Pivots!F102) -> 560 | V22: =IF(Pivots!G102="","",Pivots!G102) -> 4804
P23: =IF(Pivots!A103="","",Pivots!A103) -> C0004 | Q23: =IF(Pivots!B103="","",Pivots!B103) -> 1991 | R23: =IF(Pivots!C103="","",Pivots!C103) -> 1886 | S23: =IF(Pivots!D103="","",Pivots!D103) -> 1206 | T23: =IF(Pivots!E103="","",Pivots!E103) -> 884 | U23: =IF(Pivots!F103="","",Pivots!F103) -> 1722 | V23: =IF(Pivots!G103="","",Pivots!G103) -> 7689
P24: =IF(Pivots!A104="","",Pivots!A104) -> C0011 | Q24: =IF(Pivots!B104="","",Pivots!B104) -> 1163 | R24: =IF(Pivots!C104="","",Pivots!C104) -> 1180 | S24: =IF(Pivots!D104="","",Pivots!D104) -> 1616 | T24: =IF(Pivots!E104="","",Pivots!E104) -> 1043 | U24: =IF(Pivots!F104="","",Pivots!F104) -> 1747 | V24: =IF(Pivots!G104="","",Pivots!G104) -> 6749
P25: =IF(Pivots!A105="","",Pivots!A105) -> C0012 | Q25: =IF(Pivots!B105="","",Pivots!B105) -> 1438 | R25: =IF(Pivots!C105="","",Pivots!C105) -> 1616 | S25: =IF(Pivots!D105="","",Pivots!D105) -> 866 | T25: =IF(Pivots!E105="","",Pivots!E105) -> 829 | U25: =IF(Pivots!F105="","",Pivots!F105) -> 2070 | V25: =IF(Pivots!G105="","",Pivots!G105) -> 6819
P26: =IF(Pivots!A106="","",Pivots!A106) -> Cleveland | Q26: =IF(Pivots!B106="","",Pivots!B106) | R26: =IF(Pivots!C106="","",Pivots!C106) | S26: =IF(Pivots!D106="","",Pivots!D106) | T26: =IF(Pivots!E106="","",Pivots!E106) | U26: =IF(Pivots!F106="","",Pivots!F106) | V26: =IF(Pivots!G106="","",Pivots!G106)
P27: =IF(Pivots!A107="","",Pivots!A107) -> C0002 | Q27: =IF(Pivots!B107="","",Pivots!B107) -> 1233 | R27: =IF(Pivots!C107="","",Pivots!C107) -> 223 | S27: =IF(Pivots!D107="","",Pivots!D107) -> 1680 | T27: =IF(Pivots!E107="","",Pivots!E107) -> 990 | U27: =IF(Pivots!F107="","",Pivots!F107) -> 1508 | V27: =IF(Pivots!G107="","",Pivots!G107) -> 5634
P28: =IF(Pivots!A108="","",Pivots!A108) -> C0007 | Q28: =IF(Pivots!B108="","",Pivots!B108) -> 1598 | R28: =IF(Pivots!C108="","",Pivots!C108) -> 1907 | S28: =IF(Pivots!D108="","",Pivots!D108) -> 869 | T28: =IF(Pivots!E108="","",Pivots!E108) -> 1426 | U28: =IF(Pivots!F108="","",Pivots!F108) -> 1416 | V28: =IF(Pivots!G108="","",Pivots!G108) -> 7216
P29: =IF(Pivots!A109="","",Pivots!A109) -> C0008 | Q29: =IF(Pivots!B109="","",Pivots!B109) -> 900 | R29: =IF(Pivots!C109="","",Pivots!C109) -> 1016 | S29: =IF(Pivots!D109="","",Pivots!D109) -> 960 | T29: =IF(Pivots!E109="","",Pivots!E109) -> 940 | U29: =IF(Pivots!F109="","",Pivots!F109) -> 1193 | V29: =IF(Pivots!G109="","",Pivots!G109) -> 5009
P30: =IF(Pivots!A110="","",Pivots!A110) -> C0010 | Q30: =IF(Pivots!B110="","",Pivots!B110) -> 900 | R30: =IF(Pivots!C110="","",Pivots!C110) -> 1470 | S30: =IF(Pivots!D110="","",Pivots!D110) -> 1617 | T30: =IF(Pivots!E110="","",Pivots!E110) -> 1314 | U30: =IF(Pivots!F110="","",Pivots!F110) -> 941 | V30: =IF(Pivots!G110="","",Pivots!G110) -> 6242
P31: =IF(Pivots!A111="","",Pivots!A111) -> C0013 | Q31: =IF(Pivots!B111="","",Pivots!B111) -> 1255 | R31: =IF(Pivots!C111="","",Pivots!C111) -> 516 | S31: =IF(Pivots!D111="","",Pivots!D111) -> 1874 | T31: =IF(Pivots!E111="","",Pivots!E111) -> 1863 | U31: =IF(Pivots!F111="","",Pivots!F111) -> 1722 | V31: =IF(Pivots!G111="","",Pivots!G111) -> 7230
P32: =IF(Pivots!A112="","",Pivots!A112) -> C0015 | Q32: =IF(Pivots!B112="","",Pivots!B112) -> 1138 | R32: =IF(Pivots!C112="","",Pivots!C112) -> 1898 | S32: =IF(Pivots!D112="","",Pivots!D112) -> 1482 | T32: =IF(Pivots!E112="","",Pivots!E112) -> 846 | U32: =IF(Pivots!F112="","",Pivots!F112) -> 1154 | V32: =IF(Pivots!G112="","",Pivots!G112) -> 6518
... P38: =IF(Pivots!A118="","",Pivots!A118) -> C0014 | Q38: =IF(Pivots!B118="","",Pivots!B118) -> 1362 | R38: =IF(Pivots!C118="","",Pivots!C118) -> 1363 | S38: =IF(Pivots!D118="","",Pivots!D118) -> 1152 | T38: =IF(Pivots!E118="","",Pivots!E118) -> 777 | U38: =IF(Pivots!F118="","",Pivots!F118) -> 750 | V38: =IF(Pivots!G118="","",Pivots!G118) -> 5404

Sheet Assets
E2: Rep ID | F2: Rep Image
E3: R01 | F3: #VALUE!
E4: R02 | F4: #VALUE!
E5: R03 | F5: #VALUE!
E6: R04 | F6: #VALUE!
E7: R05 | F7: #VALUE!
E13: Rep ID | F13: Rep Image
E14: R01
E15: R02
E16: R03
E17: R04
E18: R05
